<?xml version="1.0" ?>
<!-- =================================================================================== -->
<!-- |    This document was autogenerated by xacro from ./talos_full_v2.urdf.xacro     | -->
<!-- |    EDITING THIS FILE BY HAND IS NOT RECOMMENDED                                 | -->
<!-- =================================================================================== -->
<!--

  Copyright (c) 2016, PAL Robotics, S.L.
  All rights reserved.

  This work is licensed under the Creative Commons Attribution-NonCommercial-NoDerivs 3.0 Unported License.
  To view a copy of this license, visit http://creativecommons.org/licenses/by-nc-nd/3.0/ or send a letter to
  Creative Commons, 444 Castro Street, Suite 900, Mountain View, California, 94041, USA.
-->
<robot name="talos" xmlns:controller="http://playerstage.sourceforge.net/gazebo/xmlschema/#controller" xmlns:interface="http://playerstage.sourceforge.net/gazebo/xmlschema/#interface" xmlns:sensor="http://playerstage.sourceforge.net/gazebo/xmlschema/#sensor" xmlns:xacro="http://ros.org/wiki/xacro">

  <!--************************-->
  <!--        TORSO_2  (TILT) -->
  <!--************************-->
  <link name="torso">
    <inertial>
      <origin rpy="0.00000 0.00000 0.00000" xyz="-0.04551 -0.00053 0.16386"/>
      <mass value="17.55011"/>
      <inertia ixx="0.37376900000" ixy="0.00063900000" ixz="0.01219600000" iyy="0.24790200000" iyz="0.00000700000" izz="0.28140400000"/>
    </inertial>
    <visual>
      <origin rpy="0 0 0" xyz="0 0 0"/>
      <geometry>
        <mesh filename="package://talos_data/meshes/torso/torso_2.STL" scale="1 1 1"/>
      </geometry>
      <material name="LightGrey"/>
    </visual>
    <collision>
      <origin rpy="0 0 0" xyz="0 0 0"/>
      <geometry>
        <mesh filename="package://talos_data/meshes/torso/torso_2_collision.STL" scale="1 1 1"/>
      </geometry>
    </collision>
  </link>

  <!--************************-->
  <!--        SHOULDER        -->
  <!--************************-->
  <link name="arm_left_1_link">
    <inertial>
      <mass value="2.714567"/>
      <inertia ixx="0.01237818683" ixy="-3.625571e-05" ixz="7.14472e-05" iyy="0.004191372" iyz="-0.00023639064" izz="0.01358161109"/>
      <origin rpy="0 0 0" xyz="-0.0002762 0.10060223 0.04437419"/>
    </inertial>
    <visual>
      <origin rpy="0 0 0" xyz="0 0 0"/>
      <geometry>
        <mesh filename="package://talos_data/meshes/arm/arm_1.STL" scale="1 1 1"/>
      </geometry>
      <material name="DarkGrey"/>
    </visual>
    <collision>
      <origin rpy="0 0 0" xyz="0 0 0"/>
      <geometry>
        <mesh filename="package://talos_data/meshes/arm/arm_1_collision.STL" scale="1 1 1"/>
      </geometry>
    </collision>
  </link>
  <joint name="arm_left_1_joint" type="revolute">
    <parent link="torso"/>
    <child link="arm_left_1_link"/>
    <origin rpy="0.0 0.0 0.0" xyz="0.00000 0.1575 0.23200"/>
    <axis xyz="0 0 1"/>
    <!-- v1 TALOS has 1st arm left joint (-90,30) and right joint (-30,90) -->
    <!-- v2 TALOS has 1st arm left joint (-90,50) and right joint (-50,90) -->
    <limit effort="100.0" lower="-1.57079632679" upper="0.785398163397" velocity="2.7"/>
    <dynamics damping="1.0" friction="1.0"/>
    <!--        <safety_controller k_position="20"
                          k_velocity="20"
                          soft_lower_limit="${-90.00000 * deg_to_rad + arm_eps}"
                          soft_upper_limit="${30.00000 * deg_to_rad - arm_eps}" /> -->
  </joint>
  <link name="arm_left_2_link">
    <inertial>
      <mass value="2.425086"/>
      <inertia ixx="0.01297822101" ixy="1.208791e-05" ixz="-0.00320370433" iyy="0.01380870278" iyz="-0.00012770059" izz="0.00478856621"/>
      <origin rpy="0 0 0" xyz="0.01438831 0.00092938 -0.08684268"/>
    </inertial>
    <visual>
      <origin rpy="0 0 0" xyz="0 0 0"/>
      <geometry>
        <mesh filename="package://talos_data/meshes/arm/arm_2.STL" scale="1 1 1"/>
      </geometry>
      <material name="DarkGrey"/>
    </visual>
    <collision>
      <origin rpy="0 0 0" xyz="0 0 0"/>
      <geometry>
        <mesh filename="package://talos_data/meshes/arm/arm_2_collision.STL" scale="1 1 1"/>
      </geometry>
    </collision>
  </link>
  <joint name="arm_left_2_joint" type="revolute">
    <parent link="arm_left_1_link"/>
    <child link="arm_left_2_link"/>
    <origin rpy="0.0 0.0 0.0" xyz="0.00493 0.1365 0.04673"/>
    <axis xyz="1 0 0"/>
    <limit effort="100.0" lower="0.00872664625997" upper="2.87106661953" velocity="3.66"/>
    <dynamics damping="1.0" friction="1.0"/>
    <!--        <safety_controller k_position="20"
                          k_velocity="20"
                          soft_lower_limit="${0.00000 * deg_to_rad + arm_eps}"
                          soft_upper_limit="${165.00000 * deg_to_rad - arm_eps}" /> -->
  </joint>
  <link name="arm_left_3_link">
    <inertial>
      <mass value="2.208741"/>
      <inertia ixx="0.00718831493" ixy="-0.00011563551" ixz="0.00075969733" iyy="0.00693528503" iyz="0.00042134743" izz="0.00388359007"/>
      <origin rpy="0 0 0" xyz="0.0136084 0.01241619 -0.2499004"/>
    </inertial>
    <visual>
      <origin rpy="0 0 0" xyz="0 0 0"/>
      <geometry>
        <mesh filename="package://talos_data/meshes/arm/arm_3.STL" scale="1 1 1"/>
      </geometry>
      <material name="DarkGrey"/>
    </visual>
    <collision>
      <origin rpy="0 0 0" xyz="0 0 0"/>
      <geometry>
        <mesh filename="package://talos_data/meshes/arm/arm_3_collision.STL" scale="1 1 1"/>
      </geometry>
    </collision>
  </link>
  <joint name="arm_left_3_joint" type="revolute">
    <parent link="arm_left_2_link"/>
    <child link="arm_left_3_link"/>
    <origin rpy="0.0 0.0 0.0" xyz="0.00000 0.00000 0.00000"/>
    <axis xyz="0 0 1"/>
    <limit effort="70.0" lower="-2.42600766027" upper="2.42600766027" velocity="4.58"/>
    <dynamics damping="1.0" friction="1.0"/>
    <!--       <safety_controller k_position="20"
                          k_velocity="20"
                          soft_lower_limit="${-140.0 * deg_to_rad + arm_eps}"
                          soft_upper_limit="${140.0 * deg_to_rad - arm_eps}" /> -->
  </joint>
  <!--************************-->
  <!--        ELBOW           -->
  <!--************************-->
  <link name="arm_left_4_link">
    <inertial>
      <mass value="0.877346"/>
      <inertia ixx="0.00251207716" ixy="0.00010070062" ixz="-0.00032788214" iyy="0.00275869324" iyz="0.00040022227" izz="0.00120735959"/>
      <origin rpy="0 0 0" xyz="-0.00742138 -0.0213895 -0.03312656"/>
    </inertial>
    <visual>
      <origin rpy="0 0 0" xyz="0 0 0"/>
      <geometry>
        <mesh filename="package://talos_data/meshes/arm/arm_4.STL" scale="1 1 1"/>
      </geometry>
      <material name="DarkGrey"/>
    </visual>
    <collision>
      <origin rpy="0 0 0" xyz="0 0 0"/>
      <geometry>
        <mesh filename="package://talos_data/meshes/arm/arm_4_collision.STL" scale="1 1 1"/>
      </geometry>
    </collision>
  </link>
  <joint name="arm_left_4_joint" type="revolute">
    <parent link="arm_left_3_link"/>
    <child link="arm_left_4_link"/>
    <origin rpy="0.0 0.0 0.0" xyz="0.02000 0.00000 -0.27300"/>
    <axis xyz="0 1 0"/>
    <limit effort="70.0" lower="-2.23402144255" upper="0.00349065850399" velocity="4.58"/>
    <dynamics damping="1.0" friction="1.0"/>
    <!--       <safety_controller k_position="20"
                          k_velocity="20"
                          soft_lower_limit="${-135.0 * deg_to_rad + arm_eps}"
                          soft_upper_limit="${0.0 * deg_to_rad - arm_eps}" /> -->
  </joint>

  <!--************************-->
  <!--        WRIST           -->
  <!--************************-->
  <link name="arm_left_5_link">
    <inertial>
      <mass value="1.877923"/>
      <inertia ixx="0.00349507283" ixy="1.265489e-05" ixz="1.038286e-05" iyy="0.00436830072" iyz="-9.736042e-05" izz="0.0022826337"/>
      <origin rpy="0 0 0" xyz="-6e-05 0.003262 0.079625"/>
    </inertial>
    <visual>
      <origin rpy="0 0 0" xyz="0 0 0"/>
      <geometry>
        <mesh filename="package://talos_data/meshes/arm/arm_5.STL" scale="1 1 1"/>
      </geometry>
      <material name="LightGrey"/>
    </visual>
    <collision>
      <origin rpy="0 0 0" xyz="0 0 0"/>
      <geometry>
        <mesh filename="package://talos_data/meshes/arm/arm_5_collision.STL" scale="1 1 1"/>
      </geometry>
    </collision>
  </link>
  <joint name="arm_left_5_joint" type="revolute">
    <parent link="arm_left_4_link"/>
    <child link="arm_left_5_link"/>
    <origin rpy="0.0 0.0 0.0" xyz="-0.02000 0.00000 -0.26430"/>
    <axis xyz="0 0 1"/>
    <limit effort="20.0" lower="-2.51327412287" upper="2.51327412287" velocity="1.95"/>
    <dynamics damping="1.0" friction="1.0"/>
    <!--       <safety_controller k_position="20"
                          k_velocity="20"
                          soft_lower_limit="${-145.00000 * deg_to_rad + wrist_eps}"
                          soft_upper_limit="${145.00000 * deg_to_rad - wrist_eps}" /> -->
  </joint>
  <link name="arm_left_6_link">
    <inertial>
      <mass value="0.40931"/>
      <inertia ixx="0.00010700023" ixy="-8.899e-08" ixz="-4.392e-08" iyy="0.00014101316" iyz="4.1702e-07" izz="0.00015398658"/>
      <origin rpy="0 0 0" xyz="2.1e-05 -0.001965 -0.000591"/>
    </inertial>
    <visual>
      <origin rpy="0 0 0" xyz="0 0 0"/>
      <geometry>
        <mesh filename="package://talos_data/meshes/arm/arm_6.STL" scale="1 1 1"/>
      </geometry>
      <material name="LightGrey"/>
    </visual>
    <collision>
      <origin rpy="0 0 0" xyz="0 0 0"/>
      <geometry>
        <mesh filename="package://talos_data/meshes/arm/arm_6_collision.STL" scale="1 1 1"/>
      </geometry>
    </collision>
  </link>
  <joint name="arm_left_6_joint" type="revolute">
    <parent link="arm_left_5_link"/>
    <child link="arm_left_6_link"/>
    <origin rpy="0.0 0.0 0.0" xyz="0.00000 0.00000 0.00000"/>
    <axis xyz="1 0 0"/>
    <limit effort="8.0" lower="-1.37008346282" upper="1.37008346282" velocity="1.76"/>
    <dynamics damping="1.0" friction="1.0"/>
    <!--       <safety_controller k_position="20"
                          k_velocity="20"
                          soft_lower_limit="${-80.00000 * deg_to_rad + eps_radians}"
                          soft_upper_limit="${80.00000 * deg_to_rad - eps_radians}" /> -->
  </joint>
  <link name="arm_left_7_link">
    <inertial>
      <mass value="0.308441"/>
      <inertia ixx="0.00030894317" ixy="-1.58687e-06" ixz="1.73418e-06" iyy="0.00021886181" iyz="-1.221167e-05" izz="0.00017519492"/>
      <origin rpy="0 0 0" xyz="0.007525 0.001378 -0.02463"/>
    </inertial>
    <visual>
      <origin rpy="0 0 0" xyz="0 0 0"/>
      <geometry>
        <mesh filename="package://talos_data/meshes/arm/arm_7.STL" scale="1 1 1"/>
      </geometry>
      <material name="DarkGrey"/>
    </visual>
    <collision>
      <origin rpy="0 0 0" xyz="0 0 0"/>
      <geometry>
        <mesh filename="package://talos_data/meshes/arm/arm_7_collision.STL" scale="1 1 1"/>
      </geometry>
    </collision>
  </link>
  <joint name="arm_left_7_joint" type="revolute">
    <parent link="arm_left_6_link"/>
    <child link="arm_left_7_link"/>
    <origin rpy="0.0 0.0 0.0" xyz="0.0 0.0 0.0"/>
    <axis xyz="0 1 0"/>
    <limit effort="8.0" lower="-0.680678408278" upper="0.680678408278" velocity="1.76"/>
    <dynamics damping="1.0" friction="1.0"/>
    <!--       <safety_controller k_position="20"
                          k_velocity="20"
                          soft_lower_limit="${-40.00000 * deg_to_rad + eps_radians}"
                          soft_upper_limit="${40.00000 * deg_to_rad - eps_radians}" /> -->
  </joint>
 
  <transmission name="arm_left_5_trans">
    <type>transmission_interface/SimpleTransmission</type>
    <actuator name="arm_left_5_motor">
      <mechanicalReduction>1.0</mechanicalReduction>
    </actuator>
    <joint name="arm_left_5_joint">
      <offset>0.0</offset>
      <hardwareInterface>hardware_interface/PositionJointInterface</hardwareInterface>
      <hardwareInterface>hardware_interface/EffortJointInterface</hardwareInterface>
    </joint>
  </transmission>
  <transmission name="wrist_left_trans">
    <type>transmission_interface/DifferentialTransmission</type>
    <actuator name="arm_left_6_motor">
      <role>actuator1</role>
      <mechanicalReduction>-1.0</mechanicalReduction>
    </actuator>
    <actuator name="arm_left_7_motor">
      <role>actuator2</role>
      <mechanicalReduction>1.0</mechanicalReduction>
    </actuator>
    <joint name="arm_left_6_joint">
      <role>joint1</role>
      <offset>0.0</offset>
      <mechanicalReduction>-1.0</mechanicalReduction>
      <hardwareInterface>hardware_interface/PositionJointInterface</hardwareInterface>
      <hardwareInterface>hardware_interface/EffortJointInterface</hardwareInterface>
    </joint>
    <joint name="arm_left_7_joint">
      <role>joint2</role>
      <offset>0.0</offset>
      <mechanicalReduction>-1.0</mechanicalReduction>
      <hardwareInterface>hardware_interface/PositionJointInterface</hardwareInterface>
      <hardwareInterface>hardware_interface/EffortJointInterface</hardwareInterface>
    </joint>
  </transmission>
  <transmission name="arm_left_1_trans">
    <type>transmission_interface/SimpleTransmission</type>
    <actuator name="arm_left_1_motor">
      <mechanicalReduction>1.0</mechanicalReduction>
    </actuator>
    <joint name="arm_left_1_joint">
      <offset>0.0</offset>
      <hardwareInterface>hardware_interface/PositionJointInterface</hardwareInterface>
      <hardwareInterface>hardware_interface/EffortJointInterface</hardwareInterface>
    </joint>
  </transmission>
  <transmission name="arm_left_2_trans">
    <type>transmission_interface/SimpleTransmission</type>
    <actuator name="arm_left_2_motor">
      <mechanicalReduction>1.0</mechanicalReduction>
    </actuator>
    <joint name="arm_left_2_joint">
      <offset>0.0</offset>
      <hardwareInterface>hardware_interface/PositionJointInterface</hardwareInterface>
      <hardwareInterface>hardware_interface/EffortJointInterface</hardwareInterface>
    </joint>
  </transmission>
  <transmission name="arm_left_3_trans">
    <type>transmission_interface/SimpleTransmission</type>
    <actuator name="arm_left_3_motor">
      <mechanicalReduction>1.0</mechanicalReduction>
    </actuator>
    <joint name="arm_left_3_joint">
      <offset>0.0</offset>
      <hardwareInterface>hardware_interface/PositionJointInterface</hardwareInterface>
      <hardwareInterface>hardware_interface/EffortJointInterface</hardwareInterface>
    </joint>
  </transmission>
  <transmission name="arm_left_4_trans">
    <type>transmission_interface/SimpleTransmission</type>
    <actuator name="arm_left_4_motor">
      <mechanicalReduction>1.0</mechanicalReduction>
    </actuator>
    <joint name="arm_left_4_joint">
      <offset>0.0</offset>
      <hardwareInterface>hardware_interface/PositionJointInterface</hardwareInterface>
      <hardwareInterface>hardware_interface/EffortJointInterface</hardwareInterface>
    </joint>
  </transmission>
  
  
</robot>


